ERROR 2020-03-18 16:34:58,937 - Exception on /index/list [GET]
Traceback (most recent call last):
  File "/usr/local/lib/python3.6/site-packages/flask/app.py", line 1813, in full_dispatch_request
    rv = self.dispatch_request()
  File "/usr/local/lib/python3.6/site-packages/flask/app.py", line 1799, in dispatch_request
    return self.view_functions[rule.endpoint](**req.view_args)
  File "/usr/local/lib/python3.6/site-packages/flask_restplus/api.py", line 325, in wrapper
    resp = resource(*args, **kwargs)
  File "/usr/local/lib/python3.6/site-packages/flask/views.py", line 88, in view
    return self.dispatch_request(*args, **kwargs)
  File "/usr/local/lib/python3.6/site-packages/flask_restplus/resource.py", line 44, in dispatch_request
    resp = meth(*args, **kwargs)
  File "./app/main/controller/indexController.py", line 51, in get
    api.logger.info("Looking for title {0}".format(args['title']))
AttributeError: 'Namespace' object has no attribute 'logger'
ERROR 2020-03-18 16:36:07,010 - Exception on /index/list [GET]
Traceback (most recent call last):
  File "/usr/local/lib/python3.6/site-packages/flask/app.py", line 1813, in full_dispatch_request
    rv = self.dispatch_request()
  File "/usr/local/lib/python3.6/site-packages/flask/app.py", line 1799, in dispatch_request
    return self.view_functions[rule.endpoint](**req.view_args)
  File "/usr/local/lib/python3.6/site-packages/flask_restplus/api.py", line 325, in wrapper
    resp = resource(*args, **kwargs)
  File "/usr/local/lib/python3.6/site-packages/flask/views.py", line 88, in view
    return self.dispatch_request(*args, **kwargs)
  File "/usr/local/lib/python3.6/site-packages/flask_restplus/resource.py", line 44, in dispatch_request
    resp = meth(*args, **kwargs)
  File "./app/main/controller/indexController.py", line 51, in get
    logger.info("Looking for title {0}".format(args['title']))
AttributeError: 'Namespace' object has no attribute 'logger'
